<?xml version="1.0"?>
<!-- This URDF was automatically created by SolidWorks to URDF Exporter! Originally created by Stephen Brawner (brawner@gmail.com) 
     Commit Version: 1.6.0-4-g7f85cfe  Build Version: 1.6.7995.38578
     For more information, please see http://wiki.ros.org/sw_urdf_exporter -->
<robot name="diff_robot">
  <!-- ========== LINKS & JOINTS (unchanged from your original) ========== -->
  <link name="base_footprint">
    <inertial>
      <origin xyz="0.078647 5.687E-05 0.05405" rpy="0 0 0" />
      <mass value="0.178" />
      <inertia ixx="0.00047393" ixy="3.6359E-07" ixz="-4.6904E-22" iyy="0.00070361" iyz="-2.1921E-20" izz="0.0011773" />
    </inertial>
    <visual>
      <origin xyz="0 0 0" rpy="0 0 0" />
      <geometry>
        <mesh filename="package://diff_robot/meshes/base_footprint.STL" />
      </geometry>
      <material name="">
        <color rgba="0.79216 0.81961 0.93333 1" />
      </material>
    </visual>
    <collision>
      <origin xyz="0 0 0" rpy="0 0 0" />
      <geometry>
        <mesh filename="package://diff_robot/meshes/base_footprint.STL" />
      </geometry>
    </collision>
  </link>

  <link name="base_link">
    <inertial>
      <origin xyz="0.051677 0.0029767 -0.043025" rpy="0 0 0" />
      <mass value="0.677" />
      <inertia ixx="0.0005329" ixy="1.0246E-07" ixz="-6.796E-09" iyy="0.00077273" iyz="-4.6344E-07" izz="0.0012951" />
    </inertial>
    <visual>
      <origin xyz="0 0 0" rpy="0 0 0" />
      <geometry>
        <mesh filename="package://diff_robot/meshes/base_link.STL" />
      </geometry>
      <material name="">
        <color rgba="0.79216 0.81961 0.93333 1" />
      </material>
    </visual>
    <collision>
      <origin xyz="0 0 0" rpy="0 0 0" />
      <geometry>
        <mesh filename="package://diff_robot/meshes/base_link.STL" />
      </geometry>
    </collision>
  </link>

  <joint name="base_link_joint" type="fixed">
    <origin xyz="0 0 0.03255" rpy="3.1416 0 0" />
    <parent link="base_footprint" />
    <child link="base_link" />
    <axis xyz="0 0 0" />
  </joint>

  <link name="left_wheel">
    <inertial>
      <origin xyz="-0.00044875 -5.7255E-05 -8.9504E-06" rpy="0 0 0" />
      <mass value="0.039" />
      <inertia ixx="2.822E-05" ixy="4.8128E-09" ixz="-4.3123E-10" iyy="2.8181E-05" iyz="1.4639E-10" izz="4.608E-05" />
    </inertial>
    <visual>
      <origin xyz="0 0 0" rpy="0 0 0" />
      <geometry>
        <mesh filename="package://diff_robot/meshes/left_wheel.STL" />
      </geometry>
      <material name="">
        <color rgba="0.75294 0.75294 0.75294 1" />
      </material>
    </visual>
    <collision>
      <origin xyz="0 0 0" rpy="0 0 0" />
      <geometry>
        <mesh filename="package://diff_robot/meshes/left_wheel.STL" />
      </geometry>
    </collision>
  </link>

  <joint name="left_wheel_joint" type="continuous">
    <origin xyz="0 -0.1168 0" rpy="-1.5708 0 -3.1416" />
    <parent link="base_link" />
    <child link="left_wheel" />
    <axis xyz="0 0 1" />
  </joint>

  <link name="right_wheel">
    <inertial>
      <origin xyz="-0.00044732 -6.7476E-05 8.9504E-06" rpy="0 0 0" />
      <mass value="0.039" />
      <inertia ixx="2.822E-05" ixy="6.2644E-09" ixz="3.7486E-10" iyy="2.8181E-05" iyz="2.586E-10" izz="4.608E-05" />
    </inertial>
    <visual>
      <origin xyz="0 0 0" rpy="0 0 0" />
      <geometry>
        <mesh filename="package://diff_robot/meshes/right_wheel.STL" />
      </geometry>
      <material name="">
        <color rgba="0.75294 0.75294 0.75294 1" />
      </material>
    </visual>
    <collision>
      <origin xyz="0 0 0" rpy="0 0 0" />
      <geometry>
        <mesh filename="package://diff_robot/meshes/right_wheel.STL" />
      </geometry>
    </collision>
  </link>

  <joint name="right_wheel_joint" type="continuous">
    <origin xyz="0 0.1168 0" rpy="-1.5708 0 -3.1416" />
    <parent link="base_link" />
    <child link="right_wheel" />
    <axis xyz="0 0 1" />
  </joint>

  <link name="caster_wheel">
    <inertial>
      <origin xyz="1.2545E-07 -2.7756E-17 0.0038165" rpy="0 0 0" />
      <mass value="0.122" />
      <inertia ixx="1.7798E-05" ixy="-1.1156E-20" ixz="4.7639E-20" iyy="1.6175E-05" iyz="3.8939E-21" izz="2.4954E-05" />
    </inertial>
    <visual>
      <origin xyz="0 0 0" rpy="0 0 0" />
      <geometry>
        <mesh filename="package://diff_robot/meshes/caster_wheel.STL" />
      </geometry>
      <material name="">
        <color rgba="0.75294 0.75294 0.75294 1" />
      </material>
    </visual>
    <collision>
      <origin xyz="0 0 0" rpy="0 0 0" />
      <geometry>
        <mesh filename="package://diff_robot/meshes/caster_wheel.STL" />
      </geometry>
    </collision>
  </link>

  <joint name="caster_wheel_joint" type="fixed">
    <origin xyz="0.165 0 0.0208" rpy="-3.1416 0 0" />
    <parent link="base_link" />
    <child link="caster_wheel" />
    <axis xyz="0 0 1" />
  </joint>

  <link name="esp32_cam_link">
    <inertial>
      <origin xyz="-0.0082738 0.0079268 0.00032292" rpy="0 0 0" />
      <mass value="0.01" />
      <inertia ixx="3.2036E-06" ixy="6.2464E-10" ixz="1.2633E-08" iyy="1.2669E-06" iyz="6.8227E-10" izz="1.9738E-06" />
    </inertial>
    <visual>
      <origin xyz="0 0 0" rpy="0 0 0" />
      <geometry>
        <mesh filename="package://diff_robot/meshes/esp32_cam_link.STL" />
      </geometry>
      <material name="">
        <color rgba="0.75294 0.75294 0.75294 1" />
      </material>
    </visual>
    <collision>
      <origin xyz="0 0 0" rpy="0 0 0" />
      <geometry>
        <mesh filename="package://diff_robot/meshes/esp32_cam_link.STL" />
      </geometry>
    </collision>
  </link>

  <joint name="esp32_cam_joint" type="fixed">
    <origin xyz="0.20857 0.0083034 -0.043987" rpy="-3.1416 0 0" />
    <parent link="base_link" />
    <child link="esp32_cam_link" />
    <axis xyz="0 0 0" />
  </joint>
#!/usr/bin/env python3
#
# Copyright 2023-2025 KAIA.AI
#
# Licensed under the Apache License, Version 2.0 (the "License");
# you may not use this file except in compliance with the License.
# You may obtain a copy of the License at
#
#     http://www.apache.org/licenses/LICENSE-2.0
#
# Unless required by applicable law or agreed to in writing, software
# distributed under the License is distributed on an "AS IS" BASIS,
# WITHOUT WARRANTIES OR CONDITIONS OF ANY KIND, either express or implied.
# See the License for the specific language governing permissions and
# limitations under the License.

import os, re
from ament_index_python.packages import get_package_share_path
from launch import LaunchDescription, LaunchContext
from launch.actions import IncludeLaunchDescription, DeclareLaunchArgument, OpaqueFunction
from launch.launch_description_sources import PythonLaunchDescriptionSource
from launch.substitutions import Command, LaunchConfiguration
from launch_ros.parameter_descriptions import ParameterValue
from launch_ros.actions import Node
from kaiaai import config


def make_nodes(context: LaunchContext, robot_model, use_sim_time, x_pose, y_pose, world):
    robot_model_str = context.perform_substitution(robot_model)
    use_sim_time_str = context.perform_substitution(use_sim_time)
    x_pose_str = context.perform_substitution(x_pose)
    y_pose_str = context.perform_substitution(y_pose)
    world_str = context.perform_substitution(world)

    if len(robot_model_str) == 0:
      robot_model_str = config.get_var('robot.model')

    urdf_path_name = os.path.join(
      get_package_share_path(robot_model_str),
      'urdf',
      'robot.urdf.xacro')

    robot_description = ParameterValue(Command(['xacro ', urdf_path_name]), value_type=str)

    sdf_path_name = os.path.join(
        get_package_share_path(robot_model_str),
        'sdf',
        robot_model_str,
        'model.sdf'
    )

    pkg_gazebo_ros = get_package_share_path('gazebo_ros')
    world_path_name = os.path.join(get_package_share_path('kaiaai_gazebo'), 'worlds', world_str)

    print('URDF  file name : {}'.format(urdf_path_name))
    print('SDF   file name : {}'.format(sdf_path_name))
    print('World file name : {}'.format(world_path_name))

    return [
        IncludeLaunchDescription(
            PythonLaunchDescriptionSource(
                os.path.join(pkg_gazebo_ros, 'launch', 'gzserver.launch.py')
            ),
            launch_arguments={'world': world_path_name}.items()
        ),
        Node(
            package='robot_state_publisher',
            executable='robot_state_publisher',
            name='robot_state_publisher',
            output='screen',
            parameters=[{
                'use_sim_time': use_sim_time_str.lower() == 'true',
                'robot_description': robot_description
            }]
        ),
        Node(
            package='gazebo_ros',
            executable='spawn_entity.py',
            arguments=[
                '-entity', robot_model_str,
                '-file', sdf_path_name,
                '-timeout', '180',
                '-x', x_pose_str,
                '-y', y_pose_str,
                '-z', '0.01'
            ],
            output='screen'
        )
    ]

def generate_launch_description():

    pkg_gazebo_ros = get_package_share_path('gazebo_ros')

    return LaunchDescription([
        DeclareLaunchArgument(
            name='use_sim_time',
            default_value='true',
            choices=['true', 'false'],
            description='Use simulation (Gazebo) clock if true'
        ),
        DeclareLaunchArgument(
            name='robot_model',
            default_value='',
            description='Robot description package name'
        ),
        DeclareLaunchArgument(
            name='x_pose',
            default_value='-2.0',
            description='Robot starting x position'
        ),
        DeclareLaunchArgument(
            name='y_pose',
            default_value='-0.5',
            description='Robot starting y position'
        ),
        DeclareLaunchArgument(
            name='world',
            default_value='living_room.world',
            description='World file name'
        ),
        IncludeLaunchDescription(
            PythonLaunchDescriptionSource(
                os.path.join(pkg_gazebo_ros, 'launch', 'gzclient.launch.py')
            ),
        ),
        OpaqueFunction(function=make_nodes, args=[
            LaunchConfiguration('robot_model'),
            LaunchConfiguration('use_sim_time'),
            LaunchConfiguration('x_pose'),
            LaunchConfiguration('y_pose'),
            LaunchConfiguration('world')
        ])
    ])
  <!-- ========== GAZEBO PROPS ========== -->
  <gazebo reference="base_link">
    <material>Gazebo/Blue</material>
  </gazebo>

  <gazebo reference="left_wheel">
    <mu1>1.25</mu1>
    <mu2>1.25</mu2>
    <kp>10000000.0</kp>
    <kd>1000.0</kd>
  </gazebo>

  <gazebo reference="right_wheel">
    <mu1>1.25</mu1>
    <mu2>1.25</mu2>
    <kp>10000000.0</kp>
    <kd>1000.0</kd>
  </gazebo>

  <gazebo reference="caster_wheel">
    <mu1>0.5</mu1>
    <mu2>0.5</mu2>
    <kp>10000000000.0</kp>
    <kd>10000.0</kd>
    <minDepth>0.0001</minDepth>
  </gazebo>

  <!-- Drive plugin -->
  <gazebo>
    <plugin name="diff_robot_drive" filename="libgazebo_ros_diff_drive.so">
      <ros>
        <!-- optional namespace -->
        <remapping>cmd_vel:=cmd_vel</remapping>
      </ros>
      <update_rate>30</update_rate>

      <left_joint>left_wheel_joint</left_joint>
      <right_joint>right_wheel_joint</right_joint>

      <wheel_separation>0.2336</wheel_separation>
      <wheel_diameter>0.065</wheel_diameter>

      <max_wheel_torque>0.216</max_wheel_torque>
      <max_wheel_acceleration>12.0</max_wheel_acceleration>

      <publish_odom>true</publish_odom>
      <publish_odom_tf>true</publish_odom_tf>
      <publish_wheel_tf>true</publish_wheel_tf>

      <odometry_topic>odom</odometry_topic>
      <odometry_frame>odom</odometry_frame>
      <robot_base_frame>base_footprint</robot_base_frame>
    </plugin>

    <plugin name="dif_robot_joint_state" filename="libgazebo_ros_joint_state_publisher.so">
      <ros>
        <remapping>~/out:=joint_states</remapping>
      </ros>
      <update_rate>30</update_rate>
      <joint_name>left_wheel_joint</joint_name>
      <joint_name>right_wheel_joint</joint_name>
    </plugin>
  </gazebo>

  <!-- ========== ROS2 CAMERA SENSORS ========== -->
<!-- ===================== ESP32 CAM: RGB + DEPTH ===================== -->
<gazebo reference="esp32_cam_link">

  <!-- ========== RGB CAMERA SENSOR ========== -->
  <sensor name="esp32_rgb_sensor" type="camera">
    <always_on>true</always_on>
    <update_rate>20</update_rate>
    <visualize>true</visualize>

    <camera name="esp32_rgb_cam">
      <horizontal_fov>1.047</horizontal_fov>
      <image>
        <width>640</width>
        <height>480</height>
        <format>R8G8B8</format>
      </image>
      <clip>
        <near>0.1</near>
        <far>10.0</far>
      </clip>
    </camera>

    <plugin name="esp32_rgb_controller" filename="libgazebo_ros_camera.so">
      <ros>
        <remapping>image_raw:=esp32_cam/rgb/image_raw</remapping>
        <remapping>camera_info:=esp32_cam/rgb/camera_info</remapping>
      </ros>
      <camera_name>esp32_rgb</camera_name>
      <frame_name>esp32_cam_link</frame_name>
    </plugin>
  </sensor>

  <!-- ========== ROS2 DEPTH SENSOR ========== -->
  <sensor name="esp32_depth_sensor" type="depth">
    <always_on>true</always_on>
    <update_rate>10</update_rate>
    <visualize>true</visualize>

    <camera name="esp32_depth_cam">
      <horizontal_fov>1.047</horizontal_fov>
      <image>
        <width>640</width>
        <height>480</height>
        <format>L16</format>
      </image>
      <clip>
        <near>0.1</near>
        <far>10.0</far>
      </clip>
    </camera>

    <plugin name="esp32_depth_controller" filename="libgazebo_ros_camera.so">
      <ros>
        <remapping>image_raw:=esp32_cam/depth/image_raw</remapping>
        <remapping>camera_info:=esp32_cam/depth/camera_info</remapping>
      </ros>
      <camera_name>esp32_depth</camera_name>
      <frame_name>esp32_cam_link</frame_name>
      <min_depth>0.1</min_depth>
      <max_depth>100.0</max_depth>
      <point_cloud>true</point_cloud>
    </plugin>

  </sensor>

</gazebo>

</robot>
