<?xml version="1.0"?>
<!-- This URDF was automatically created by SolidWorks to URDF Exporter! Originally created by Stephen Brawner (brawner@gmail.com) 
     Commit Version: 1.6.0-4-g7f85cfe  Build Version: 1.6.7995.38578
     For more information, please see http://wiki.ros.org/sw_urdf_exporter -->
<robot name="diff_robot">
  <!-- ========== LINKS & JOINTS (unchanged from your original) ========== -->
  <link name="base_footprint">
    <inertial>
      <origin xyz="0.078647 5.687E-05 0.05405" rpy="0 0 0" />
      <mass value="0.178" />
      <inertia ixx="0.00047393" ixy="3.6359E-07" ixz="-4.6904E-22" iyy="0.00070361" iyz="-2.1921E-20" izz="0.0011773" />
    </inertial>
    <visual>
      <origin xyz="0 0 0" rpy="0 0 0" />
      <geometry>
        <mesh filename="package://diff_robot/meshes/base_footprint.STL" />
      </geometry>
      <material name="">
        <color rgba="0.79216 0.81961 0.93333 1" />
      </material>
    </visual>
    <collision>
      <origin xyz="0 0 0" rpy="0 0 0" />
      <geometry>
        <mesh filename="package://diff_robot/meshes/base_footprint.STL" />
      </geometry>
    </collision>
  </link>

  <link name="base_link">
    <inertial>
      <origin xyz="0.051677 0.0029767 -0.043025" rpy="0 0 0" />
      <mass value="0.677" />
      <inertia ixx="0.0005329" ixy="1.0246E-07" ixz="-6.796E-09" iyy="0.00077273" iyz="-4.6344E-07" izz="0.0012951" />
    </inertial>
    <visual>
      <origin xyz="0 0 0" rpy="0 0 0" />
      <geometry>
        <mesh filename="package://diff_robot/meshes/base_link.STL" />
      </geometry>
      <material name="">
        <color rgba="0.79216 0.81961 0.93333 1" />
      </material>
    </visual>
    <collision>
      <origin xyz="0 0 0" rpy="0 0 0" />
      <geometry>
        <mesh filename="package://diff_robot/meshes/base_link.STL" />
      </geometry>
    </collision>
  </link>

  <joint name="base_link_joint" type="fixed">
    <origin xyz="0 0 0.03255" rpy="3.1416 0 0" />
    <parent link="base_footprint" />
    <child link="base_link" />
    <axis xyz="0 0 0" />
  </joint>

  <link name="left_wheel">
    <inertial>
      <origin xyz="-0.00044875 -5.7255E-05 -8.9504E-06" rpy="0 0 0" />
      <mass value="0.039" />
      <inertia ixx="2.822E-05" ixy="4.8128E-09" ixz="-4.3123E-10" iyy="2.8181E-05" iyz="1.4639E-10" izz="4.608E-05" />
    </inertial>
    <visual>
      <origin xyz="0 0 0" rpy="0 0 0" />
      <geometry>
        <mesh filename="package://diff_robot/meshes/left_wheel.STL" />
      </geometry>
      <material name="">
        <color rgba="0.75294 0.75294 0.75294 1" />
      </material>
    </visual>
    <collision>
      <origin xyz="0 0 0" rpy="0 0 0" />
      <geometry>
        <mesh filename="package://diff_robot/meshes/left_wheel.STL" />
      </geometry>
    </collision>
  </link>

  <joint name="left_wheel_joint" type="continuous">
    <origin xyz="0 -0.1168 0" rpy="-1.5708 0 -3.1416" />
    <parent link="base_link" />
    <child link="left_wheel" />
    <axis xyz="0 0 1" />
  </joint>

  <link name="right_wheel">
    <inertial>
      <origin xyz="-0.00044732 -6.7476E-05 8.9504E-06" rpy="0 0 0" />
      <mass value="0.039" />
      <inertia ixx="2.822E-05" ixy="6.2644E-09" ixz="3.7486E-10" iyy="2.8181E-05" iyz="2.586E-10" izz="4.608E-05" />
    </inertial>
    <visual>
      <origin xyz="0 0 0" rpy="0 0 0" />
      <geometry>
        <mesh filename="package://diff_robot/meshes/right_wheel.STL" />
      </geometry>
      <material name="">
        <color rgba="0.75294 0.75294 0.75294 1" />
      </material>
    </visual>
    <collision>
      <origin xyz="0 0 0" rpy="0 0 0" />
      <geometry>
        <mesh filename="package://diff_robot/meshes/right_wheel.STL" />
      </geometry>
    </collision>
  </link>

  <joint name="right_wheel_joint" type="continuous">
    <origin xyz="0 0.1168 0" rpy="-1.5708 0 -3.1416" />
    <parent link="base_link" />
    <child link="right_wheel" />
    <axis xyz="0 0 1" />
  </joint>

  <link name="caster_wheel">
    <inertial>
      <origin xyz="1.2545E-07 -2.7756E-17 0.0038165" rpy="0 0 0" />
      <mass value="0.122" />
      <inertia ixx="1.7798E-05" ixy="-1.1156E-20" ixz="4.7639E-20" iyy="1.6175E-05" iyz="3.8939E-21" izz="2.4954E-05" />
    </inertial>
    <visual>
      <origin xyz="0 0 0" rpy="0 0 0" />
      <geometry>
        <mesh filename="package://diff_robot/meshes/caster_wheel.STL" />
      </geometry>
      <material name="">
        <color rgba="0.75294 0.75294 0.75294 1" />
      </material>
    </visual>
    <collision>
      <origin xyz="0 0 0" rpy="0 0 0" />
      <geometry>
        <mesh filename="package://diff_robot/meshes/caster_wheel.STL" />
      </geometry>
    </collision>
  </link>

  <joint name="caster_wheel_joint" type="fixed">
    <origin xyz="0.165 0 0.0208" rpy="-3.1416 0 0" />
    <parent link="base_link" />
    <child link="caster_wheel" />
    <axis xyz="0 0 1" />
  </joint>

  <link name="esp32_cam_link">
    <inertial>
      <origin xyz="-0.0082738 0.0079268 0.00032292" rpy="0 0 0" />
      <mass value="0.01" />
      <inertia ixx="3.2036E-06" ixy="6.2464E-10" ixz="1.2633E-08" iyy="1.2669E-06" iyz="6.8227E-10" izz="1.9738E-06" />
    </inertial>
    <visual>
      <origin xyz="0 0 0" rpy="0 0 0" />
      <geometry>
        <mesh filename="package://diff_robot/meshes/esp32_cam_link.STL" />
      </geometry>
      <material name="">
        <color rgba="0.75294 0.75294 0.75294 1" />
      </material>
    </visual>
    <collision>
      <origin xyz="0 0 0" rpy="0 0 0" />
      <geometry>
        <mesh filename="package://diff_robot/meshes/esp32_cam_link.STL" />
      </geometry>
    </collision>
  </link>

  <joint name="esp32_cam_joint" type="fixed">
    <origin xyz="0.20857 0.0083034 -0.043987" rpy="-3.1416 0 0" />
    <parent link="base_link" />
    <child link="esp32_cam_link" />
    <axis xyz="0 0 0" />
  </joint>

</robot>
